Traceback (most recent call last):
  File "<pyshell#41>", line 1, in <module>
    c=pyodbc.connect('')
Error: ('IM002', '[IM002] [Microsoft][ODBC Driver Manager] Data source name not found and no default driver specified (0) (SQLDriverConnectW)')

