from django.contrib.sites.models import Site
class SignUpForm(forms.Form):
    # ... Other fields ...
    url = forms.URLField(label='URL for new site, eg: example.com')

    def clean_url(self):
        url = self.cleaned_data['url']
        try:
            a = Site.objects.get(domain=url)

        except Site.DoesNotExist:
            return url

        else:
            raise forms.ValidationError("That URL is already in the database.  Please submit a unique URL.")

    def clean(self):
        # Other form cleaning stuff.  I don't *think* this is causing the grief

ValidationError
clean_url()
if Site.objects.get(domain=url):
    raise forms.ValidationError("That URL is already in the database.  Please submit a unique URL.")

DoesNotExist
