While loading migration 'whatever.0001_initial':
Traceback (most recent call last):
 File "manage.py", line 14, in <module> execute_manager(settings)

...tons of other stuff..

   raise KeyError("The model '%s' from the app '%s' is not available in this migration." % (model, app))
KeyError: "The model 'appuser' from the app 'whatever' is not available in this migration."

class AppUser(models.Model):
    person = models.OneToOneField('Person')
    user = models.ForeignKey(User, unique=True)
    class Meta:
        permissions = (
            ('is_one', 'one'),
            ('is_two', 'two')
        )
    def __unicode__(self):
        return self.person.__unicode__()

    # Adding model 'AppUser'
    db.create_table('app_appuser', (
        ('person', models.OneToOneField(orm.Person)),
        ('id', models.AutoField(primary_key=True)),
        ('user', models.ForeignKey(orm['auth.User'], unique=True)),
    ))
    db.send_create_signal('app', ['AppUser'])
    ...
    'app.appuser': {
        'Meta': {'permissions': "(('is_one','one'),('is_two','two'))"},
        'id': ('models.AutoField', [], {'primary_key': 'True'}),
        'person': ('models.OneToOneField', ["'Person'"], {}),
        'user': ('models.ForeignKey', ['User'], {'unique': 'True'})
    },

manage.py migrate app

